Workbook

Sheet Resumen
B2: Resumen de Ponderacion y Horas
B4: Curso | C4: 781 - Organización de Lenguajes y Compiladores 2
B5: Semestre que aplica | C5: Segundo Semestre 2026
B6: Total de Puntos del Laboratorio
A8: * Esta sección se auto completa al momento en que se llene a la información de la planificación
A9: ** Tomar como base la distribución realizada por el coordinador del area del curso en el documento de criterios y expectativas
A10: Tipo de Actividad | B10: Ponderacion | C10: Horas utilizadas | D10: Aspectos clave que debe abordar | G10: Valor Maximo Recomendado
A11: Actividades durante el peridodo de laboratorio | B11: =S.2!C7+S.3!C7+S.4!C7+S.5!C7+S.6!C7+S.7!C7+S.8!C7+S.9!C7+S.10!C7+S.11!C7 -> 0 | C11: 0 | G11: 10
A12: Proyectos | B12: =Proyectos!C6 -> 90 | C12: =Proyectos!C5 -> 75 | G12: 60
A13: Prácticas | B13: =Practicas!C6 -> 0 | C13: =Practicas!C5 -> 0 | G13: 20
A14: Tareas | B14: =Tareas!C6 -> 10 | C14: =Tareas!C5 -> 8 | G14: 10
A15: Total | B15: =SUM(B11:B14) -> 100 | C15: =SUM(C11:C14) -> 83 | D15: Validacion | E15: =IFERROR(__xludf.DUMMYFUNCTION("LET( nombres,A11:A14, p,B11:B14, m,G11:G14, t,SUM(p), exceden, IFERROR(TEXTJOIN(""; "", TRUE, FILTER(nombres&"" (""&p&"">""&m&"")"", p>m)), """"), negs, IF(COUNTIF(p,""<0"")>0, ""Hay valores negativos"", """"), totalmsg, IF(t<>100, ""Total ≠"&" 100 (actual ""&t&"")"", """"), excesomsg, IF(exceden<>"""", ""Exceden: ""&exceden, """"), msg, TEXTJOIN("" | "", TRUE, totalmsg, negs, excesomsg), IF(msg="""", ""✅ Distribución válida"", ""❌ Revisar: ""&msg) )"),"❌ Revisar: Exceden: Proyectos (90>60)") -> ❌ Revisar: Exceden: Proyectos (90>60)

Sheet Competencias
B1: Competencias que se formaran en el Segundo Semestre 2026
B2: Curso | C2: 781 - Organización de Lenguajes y Compiladores 2
B3: Semestre que aplica | C3: Segundo Semestre 2026
B5: Competencias relacionadas al perfil del egresado (Especifica) | I5: Competencias relacionadas al perfil del egresado (General)
B6: 1 | C6: Demuestra pensamiento crítico, actitud investigativa y rigor analítico en el planteamiento y la resolución de problemas complejos. | I6: 1 | J6: Aplica principios básicos de ingeniería, ciencias de computación y sistemas de información y comunicación, en la formulación y resolución adecuada de problemas complejos.
B7: 2 | C7: Demuestra destreza y habilidad en la selección, uso y adaptación de herramientas metodológicas, tecnológicas, equipos especializados y en la lectura e interpretación de datos, pertinentes al contexto de su ejercicio profesional. | I7: 2 | J7: Aplica estándares de calidad, eficiencia y seguridad en la implementación adecuada de soluciones de software, hardware y TIC en general.
B8: 3 | C8: Toma decisiones profesionales con base en fundamentos teóricos, datos e información pertinente, válida y confiable. | I8: 3 | J8: Actualiza permanente sus conocimientos relacionados con TIC en general, apoyándose en las estrategias de aprendizaje apropiadas.
B11: No | C11: Tipo | D11: Verbo en Presente | E11: Objeto de la acción | G11: [Palabras conectoreas] Herramientas o metodología | H11: [Palabras conectoreas] Condiciones específicas | J11: Nivel
B12: 1 | C12: General | D12: Identifica | E12: motivaciones y estructura esencial de un compilador | G12: mediante un repaso práctico de análisis sintáctico | H12: para establecer las bases teóricas del curso | J12: Comprender
C13: =D12 & " " & E12 & " " &G12& " " &H12& " " -> Identifica motivaciones y estructura esencial de un compilador mediante un repaso práctico de análisis sintáctico para establecer las bases teóricas del curso
B14: 2 | C14: Especifica | D14: Analiza | E14: estructuras de lenguaje | G14: mediante la aplicación de reglas formales | H14: para la generación de gramáticas | J14: Analizar
C15: =D14 & " " & E14 & " " &G14& " " &H14& " " -> Analiza estructuras de lenguaje mediante la aplicación de reglas formales para la generación de gramáticas
B16: 3 | C16: Especifica | D16: Analiza | E16: la semántica de un lenguaje de programación | G16: mediante la validación de tipos, alcance y estructuras de control | H16: para determinar la corrección de expresiones y sentencias | J16: Analizar
C17: =D16 & " " & E16 & " " &G16& " " &H16& " " -> Analiza la semántica de un lenguaje de programación mediante la validación de tipos, alcance y estructuras de control para determinar la corrección de expresiones y sentencias
B18: 4 | C18: Especifica | D18: Evalua | E18: la representacion semantica de funciones y objetos | G18: mediante el análisis de alcance, tipos y tabla de simbolos | H18: para determinar su correcta representación en interpretes y compiladores | J18: Evaluar
C19: =D18 & " " & E18 & " " &G18& " " &H18& " " -> Evalua la representacion semantica de funciones y objetos mediante el análisis de alcance, tipos y tabla de simbolos para determinar su correcta representación en interpretes y compiladores
B20: 5 | C20: Especifica | D20: Analiza | E20: las equivalencias sintácticas y semánticas de un lenguaje de alto nivel | G20: mediante el mapeo de construcciones a instrucciones de Representación Intermedia | H20: tales como C3D, cuádruplas o Bytecode. | J20: Comprender
C21: =D20 & " " & E20 & " " &G20& " " &H20& " " -> Analiza las equivalencias sintácticas y semánticas de un lenguaje de alto nivel mediante el mapeo de construcciones a instrucciones de Representación Intermedia tales como C3D, cuádruplas o Bytecode.
B22: 6 | C22: Especifica | D22: Generar | E22: un intérprete | G22: utilizando herramientas generadoras de parser en un lenguaje dado | H22: realizando el análisis semántico durante la ejecución. | J22: Aplicar
C23: =D22 & " " & E22 & " " &G22& " " &H22& " " -> Generar un intérprete utilizando herramientas generadoras de parser en un lenguaje dado realizando el análisis semántico durante la ejecución.
B24: 7 | C24: Especifica | D24: Generar | E24: un compilador | G24: utilizando como representación intermedia | H24: lenguajes ensambladores como RISC-V o Aarch64 | J24: Crear
C25: =D24 & " " & E24 & " " &G24& " " &H24& " " -> Generar un compilador utilizando como representación intermedia lenguajes ensambladores como RISC-V o Aarch64 | L25: Manual de competencias: https://drive.google.com/file/d/1n5es0M20vXxa7i4eLN7pbgTXc2C1dmCQ/view?usp=sharing
L26: Video de como hacer competencias: https://youtu.be/C8Q9dKo4t-w?si=yErgF_ihe1tsaHM0
B28: Si las competencias son las misma que el semetre anterior compartenos tu opinion de porque no se cambiaron

Sheet Diseño
B2: Diseño de Contenido Curricular
B4: Curso | C4: 781 - Organización de Lenguajes y Compiladores 2
B5: semestre que aplica | C5: Segundo Semestre 2026
B8: No. | C8: Competencia | D8: Nombre de la Unidad | E8: Tema | F8: Subtema | G8: Mes | H8: Semana
B9: 1 | C9: Identifica motivaciones y estructura esencial de un compilador mediante un repaso práctico de análisis sintáctico para establecer las bases teóricas del curso | D9: 1 | E9: Visión General del Curso | F9: Motivaciones para estudiar compiladores | G9: julio | H9: 1
B10: 2 | C10: Identifica motivaciones y estructura esencial de un compilador mediante un repaso práctico de análisis sintáctico para establecer las bases teóricas del curso | D10: 1 | E10: Visión General del Curso | F10: Breve Historia del Compilador | G10: julio | H10: 1
B11: 3 | C11: Identifica motivaciones y estructura esencial de un compilador mediante un repaso práctico de análisis sintáctico para establecer las bases teóricas del curso | D11: 1 | E11: Visión General del Curso | F11: Estructura de un Compilador | G11: julio | H11: 1
B12: 4 | C12: Identifica motivaciones y estructura esencial de un compilador mediante un repaso práctico de análisis sintáctico para establecer las bases teóricas del curso | D12: 1 | E12: Visión General del Curso | F12: Repaso Análisis Sintáctico | G12: julio | H12: 1
B13: 5 | C13: Analiza estructuras de lenguaje mediante la aplicación de reglas formales para la generación de gramáticas | D13: 1 | E13: Análisis Sintáctico | F13: Análisis Descendente | G13: julio | H13: 2
B14: 6 | C14: Analiza estructuras de lenguaje mediante la aplicación de reglas formales para la generación de gramáticas | D14: 1 | E14: Análisis Sintáctico | F14: Análisis Ascendente | G14: julio | H14: 2
B15: 7 | C15: Analiza estructuras de lenguaje mediante la aplicación de reglas formales para la generación de gramáticas | D15: 1 | E15: Análisis Sintáctico | F15: Resolución de ambigüedades sintácticas | G15: julio | H15: 2
B16: 8 | C16: Analiza estructuras de lenguaje mediante la aplicación de reglas formales para la generación de gramáticas | D16: 1 | E16: Análisis Sintáctico | F16: Esquemas de Traducción | G16: julio | H16: 2
B17: 9 | C17: Analiza la semántica de un lenguaje de programación mediante la validación de tipos, alcance y estructuras de control para determinar la corrección de expresiones y sentencias | D17: 1 | E17: Análisis Semántico | F17: Atributos Sintetizados y Heredados | G17: agosto | H17: 3
B18: 10 | C18: Analiza la semántica de un lenguaje de programación mediante la validación de tipos, alcance y estructuras de control para determinar la corrección de expresiones y sentencias | D18: 1 | E18: Análisis Semántico | F18: Alcance y Tabla de Símbolos | G18: agosto | H18: 3
B19: 11 | C19: Analiza la semántica de un lenguaje de programación mediante la validación de tipos, alcance y estructuras de control para determinar la corrección de expresiones y sentencias | D19: 1 | E19: Análisis Semántico | F19: Validación de Tipos | G19: agosto | H19: 3
B20: 12 | C20: Analiza la semántica de un lenguaje de programación mediante la validación de tipos, alcance y estructuras de control para determinar la corrección de expresiones y sentencias | D20: 1 | E20: Análisis Semántico | F20: Entornos | G20: agosto | H20: 3
... B57: 49 | C57: Generar un compilador utilizando como representación intermedia lenguajes ensambladores como RISC-V o Aarch64 | D57: 3 | E57: Optimización de la generación de código | F57: Algotimo para obtener registros vacíos del descriptor de registros en la generación de código | G57: Noviembre | H57: 12
B58: 50
B59: 51
B60: 52
B61: 53
B62: 54
B63: 55
B64: 56
B65: 57
B66: 58
B67: 59
B68: 60
B69: 61
... B108: 100

Sheet Semana Diagnostico
B2: Diseño de Contenido Curricular
B4: Curso | C4: ='Diseño'!C4 -> 781 - Organización de Lenguajes y Compiladores 2
B5: Semana | C5: 1
B6: Tiempo | C6: =B15+B22+B29+B42+B57+C58+B36 -> 100
K8: Estos puntos son recomendaciones de los puntos a tratar durante tu presentacion, si no usaras estos eres libre de agregar mas filas para indicar que haras. En los recuadros de la derecha colocar breve resumen de lo que planeas decir. No debes ser muy especifico seran pequeñas anotaciones que te ayudaran a recordar lo que planeaste
A9: 1. Bienvenida y Presentación | G9: Tiempo Aproximado | H9: 15
G10: No puedes excederte mas de 15 minutos
A11: Nombre y Formacion Academica | B11: Presentacion del tutor,
A12: Experiencia docente y profecional
A13: Rol del auxiliar dentro del curso (funciones, actividades y apoyo a los estudiantes). | B13: Responder dudas que quedaron de la magistral, facilitar ejercicios y material de estudio
A14: Expectativas sobre la dinámica del curso
A15: Tiempo que emplearas | B15: 15
A18: 2. Evaluación de Conocimientos Previos | G18: Tiempo Aproximado | H18: =B22 -> 15
G19: No puedes excederte mas de 15 minutos | K19: En los recuadors de la derecha deberas colocar las preguntas que planeas realizar con sus respectivas respuestas. En el segundo recuadro deberas colocar un breve resumne de lo que tines planificado para la parte practica del curso previo al que estas impartiendo.
A20: Redactaras de 15 a 20 preguntas con sus respectivas respuestas , por lo que debes escoge los temas que evaluaras | B20: Enlaces: kahoot, forms,
A21: Redactaras una parte practica para realizar la evaluacion de conocimientos previos
A22: Tiempo que emplearas | B22: 15
A25: 3. Presentación de los Estudiantes | G25: Tiempo Aproximado | H25: =B29 -> 15
G26: No puedes excederte mas de 15 minutos
A27: Seleccion al Azar de 5 Estudiantes | B27: Ruleta para que pasen estudiantes | K27: En el primer recuadro colocaras la metodollogia que adoptaras para la eleccion de los estudiantes. En el segundo recuadro colocaras la redaccion de las preguntas que comprendan los siguientes puntos respecto al estudiante: Nombre. Intereses y expectativas sobre el curso. Experiencia previa relacionada con el curso (si aplica). Un dato curioso sobre sí mismo. Consideras que la prueba de conociminetos previos esta acorde al conocimiento que se te brindo en su momento Que tan comodo se sintio con la prueba anterior.
A28: Indica las preguntas que responderan los estudiantes afortunados
A29: Tiempo que emplearas | B29: 15
A32: 4. Senso de Horarios de Calificación | G32: Tiempo Aproximado | H32: =B36 -> 5
A33: Deberas estar recordando que deben contestar el formulario asi mismo dejar el link fijado en la llamada | G33: Esta actividad quedara abierta hasta el fin de la clase. pero emplearas 5 min especificos para la actividad
A34: Link de google forms donde este el cuestionario | B34: Forms: sensos. | K34: Esta actividad te ayudara a realizar un senso de posibles horarios de calificacion y que tus estudiantes esten enterados y puedan preveer los dias de calificacion y asi mismo el horario. Deberas colocar en los reacuadros de la derecha link de Google form libre para correos intitucionales, esto para garantizar una sola respuesta por estudiante. TAmbien deberas colocar los posibles horarios y dias que tentativamente tendrias disponibles. para colocarlos en el google form.
A35: Dias y posibles Horarios de calificacion
A36: Tiempo que emplearas | B36: 5
A39: 5. Mostrar Programa del Curso | G39: Tiempo Aproximado | H39: =B42 -> 35
G40: No puedes excederte mas de 30 minutos
A41: Indicaciones | B41: Mostrar material de estudio, contacto, distribución de punteo en proyectos, tareas y actividades (No extenderse mucho con la lectura del Programa). Terminar con los subtemas
A42: Tiempo que emplearas | B42: 35
A44: 5.1 Contenido
A45: No. | B45: Unidad | D45: Tema | F45: Sub Tema
A46: 1 | B46: =IFERROR(__xludf.DUMMYFUNCTION("FILTER('Diseño'!D:D,'Diseño'!H:H=$C$5)"),1.0) -> 1 | D46: =IFERROR(__xludf.DUMMYFUNCTION("FILTER('Diseño'!E:E,'Diseño'!H:H=$C$5)"),"Visión General del Curso") -> Visión General del Curso | F46: =IFERROR(__xludf.DUMMYFUNCTION("FILTER('Diseño'!F:F,'Diseño'!H:H=$C$5)"),"Motivaciones para estudiar compiladores") -> Motivaciones para estudiar compiladores
A47: 2 | B47: =IFERROR(__xludf.DUMMYFUNCTION("""COMPUTED_VALUE"""),1.0) -> 1 | D47: =IFERROR(__xludf.DUMMYFUNCTION("""COMPUTED_VALUE"""),"Visión General del Curso") -> Visión General del Curso | F47: =IFERROR(__xludf.DUMMYFUNCTION("""COMPUTED_VALUE"""),"Breve Historia del Compilador") -> Breve Historia del Compilador
A48: 3 | B48: =IFERROR(__xludf.DUMMYFUNCTION("""COMPUTED_VALUE"""),1.0) -> 1 | D48: =IFERROR(__xludf.DUMMYFUNCTION("""COMPUTED_VALUE"""),"Visión General del Curso") -> Visión General del Curso | F48: =IFERROR(__xludf.DUMMYFUNCTION("""COMPUTED_VALUE"""),"Estructura de un Compilador") -> Estructura de un Compilador
A49: 4 | B49: =IFERROR(__xludf.DUMMYFUNCTION("""COMPUTED_VALUE"""),1.0) -> 1 | D49: =IFERROR(__xludf.DUMMYFUNCTION("""COMPUTED_VALUE"""),"Visión General del Curso") -> Visión General del Curso | F49: =IFERROR(__xludf.DUMMYFUNCTION("""COMPUTED_VALUE"""),"Repaso Análisis Sintáctico") -> Repaso Análisis Sintáctico
A50: 5
A51: 6
A52: 7
...

Sheet S.2
B2: Diseño de la Sesión de Laboratorio
B4: Curso | C4: ='Diseño'!C4 -> 781 - Organización de Lenguajes y Compiladores 2
B5: Semana | C5: 2
B6: Tiempo | C6: =H10+H21+H44+H71 -> 100
B7: Ponderación | C7: =B49+B63 -> 0
B8: Validación de Tiempo | C8: =IF(H44<=0, "❌ ERROR: La Actividad 1 debe tener un tiempo mayor a 0.", IF(H21>60, "❌ ERROR: El 'Área de Conocimiento' no puede exceder los 60 min.", IF(C6<100, "❌ ERROR: El tiempo total debe ser de al menos 100 min.", "✅ VALIDACIÓN CORRECTA"))) -> ✅ VALIDACIÓN CORRECTA
A10: 1. Área Actitudinal (Saber Ser) | G10: Tiempo Aproximado | H10: =B13 -> 5
G11: No puede exceder los 5 minutos
A12: Nombre del Valor | B12: Integridad y Veracidad Técnica
A13: Tiempo Aproximado | B13: 5
A14: Descripcion
A15: La integridad en la ingeniería de sistemas implica el compromiso con la precisión técnica y el seguimiento riguroso de estándares, garantizando que el software se comporte de manera predecible. La veracidad asegura que los reportes del sistema (como el manejo de errores) sean reflejos exactos y transparentes de la lógica procesada.
A17: Como se relaciona con los conocimientos de la sesion y se aplicaria
A18: Al resolver ambigüedades, el ingeniero actúa con integridad para garantizar una interpretación única y lógica de la gramática. Asimismo, un manejo de errores veraz proporciona mensajes precisos que guían al desarrollador sin ambigüedades, evitando comportamientos arbitrarios en el software final.
A21: 2. Área Conocimiento (Saber) | G21: Tiempo Aproximado | H21: =SUM(D39:H42) -> 60
G22: No puede exceder los 60 minutos
A23: Competencia a desarrollar | B23: Analiza estructuras de lenguaje mediante la aplicación de reglas formales para la generación de gramáticas
A24: Competencia a desarrollar
A26: 2.1 Contenido
A27: No. | B27: Unidad | D27: Tema | F27: Sub Tema
A28: 1 | B28: =IFERROR(__xludf.DUMMYFUNCTION("FILTER('Diseño'!D:D,'Diseño'!H:H=$C$5)"),1.0) -> 1 | D28: =IFERROR(__xludf.DUMMYFUNCTION("FILTER('Diseño'!E:E,'Diseño'!H:H=$C$5)"),"Análisis Sintáctico") -> Análisis Sintáctico | F28: =IFERROR(__xludf.DUMMYFUNCTION("FILTER('Diseño'!F:F,'Diseño'!H:H=$C$5)"),"Análisis Descendente") -> Análisis Descendente
A29: 2 | B29: =IFERROR(__xludf.DUMMYFUNCTION("""COMPUTED_VALUE"""),1.0) -> 1 | D29: =IFERROR(__xludf.DUMMYFUNCTION("""COMPUTED_VALUE"""),"Análisis Sintáctico") -> Análisis Sintáctico | F29: =IFERROR(__xludf.DUMMYFUNCTION("""COMPUTED_VALUE"""),"Análisis Ascendente") -> Análisis Ascendente
A30: 3 | B30: =IFERROR(__xludf.DUMMYFUNCTION("""COMPUTED_VALUE"""),1.0) -> 1 | D30: =IFERROR(__xludf.DUMMYFUNCTION("""COMPUTED_VALUE"""),"Análisis Sintáctico") -> Análisis Sintáctico | F30: =IFERROR(__xludf.DUMMYFUNCTION("""COMPUTED_VALUE"""),"Resolución de ambigüedades sintácticas") -> Resolución de ambigüedades sintácticas
A31: 4 | B31: =IFERROR(__xludf.DUMMYFUNCTION("""COMPUTED_VALUE"""),1.0) -> 1 | D31: =IFERROR(__xludf.DUMMYFUNCTION("""COMPUTED_VALUE"""),"Análisis Sintáctico") -> Análisis Sintáctico | F31: =IFERROR(__xludf.DUMMYFUNCTION("""COMPUTED_VALUE"""),"Esquemas de Traducción") -> Esquemas de Traducción
A32: 5
A33: 6
A34: 7
A36: 2.2 Recursos Educativos
A38: Tipo de Recurso a utilizar | B38: Tipo | C38: Valor maximo recomendado en Minutos | D38: Tiempo Aproximado ( unicamente el valor de minutos ) | I38: Validacion
A39: Presentacion | B39: Obligatorio | C39: 30 | D39: 20 | I39: =IF(D39<=C39,"Correcto", "Corregir") -> Correcto
A40: Video | B40: Obligatorio | C40: 6 | I40: =IF(D40<=C40,"Correcto", "Corregir") -> Correcto
A41: Lectura | B41: Optativo | C41: 10 | I41: =IF(D41<=C41,"Correcto", "Corregir") -> Correcto
A42: Ejercicio Demostrativo | B42: Obligatorio | C42: 30 | D42: 40 | I42: =IF(D42<=C42,"Correcto", "Corregir") -> Corregir
A44: 3. Área de Habilidades (Saber Hacer) | G44: Tiempo Aproximado | H44: =B50 -> 30
G45: Tiene que estar en un rango de 30 a 50 minutos
A46: Actividad 1 (Obligatoria)
A47: Competencia que predomina en la actividad | B47: Analiza estructuras de lenguaje mediante la aplicación de reglas formales para la generación de gramáticas
A48: Tipo de Actividad | B48: Ejercicio practico
A49: Ponderación
A50: Tiempo Aproximado | B50: 30
...

Sheet S.3
B2: Diseño de la Sesión de Laboratorio
B4: Curso | C4: ='Diseño'!C4 -> 781 - Organización de Lenguajes y Compiladores 2
B5: Semana | C5: 3
B6: Tiempo | C6: =H10+H21+H44+H71 -> 100
B7: Ponderación | C7: =B49+B63 -> 0
B8: Validación de Tiempo | C8: =IF(H44<=0, "❌ ERROR: La Actividad 1 debe tener un tiempo mayor a 0.", IF(H21>60, "❌ ERROR: El 'Área de Conocimiento' no puede exceder los 60 min.", IF(C6<100, "❌ ERROR: El tiempo total debe ser de al menos 100 min.", "✅ VALIDACIÓN CORRECTA"))) -> ✅ VALIDACIÓN CORRECTA
A10: 1. Área Actitudinal (Saber Ser) | G10: Tiempo Aproximado | H10: =B13 -> 5
G11: Tiene que estar en un rango de 3 a 5 minutos
A12: Nombre del Valor | B12: Rigor y Precisión Técnica
A13: Tiempo Aproximado | B13: 5
A14: Descripcion
A15: Es el compromiso con la exactitud y el cumplimiento estricto de las especificaciones lógicas en la construcción de sistemas. Se traduce en una atención meticulosa a los detalles técnicos para evitar errores de interpretación que comprometan la funcionalidad.
A17: Como se relaciona con los conocimientos de la sesion y se aplicaria
A18: Se aplica en el Análisis Semántico al validar tipos y gestionar ámbitos en la Tabla de Símbolos. El rigor asegura que las reglas de visibilidad y compatibilidad se cumplan sin excepciones, garantizando que el compilador detecte inconsistencias lógicas y genere un programa robusto y confiable.
A21: 2. Área Conocimiento (Saber) | G21: Tiempo Aproximado | H21: =SUM(D39:H42) -> 60
G22: No puede exceder los 60 minutos
A23: Competencia a desarrollar | B23: Analiza la semántica de un lenguaje de programación mediante la validación de tipos, alcance y estructuras de control para determinar la corrección de expresiones y sentencias
A24: Competencia a desarrollar
A26: 2.1 Contenido
A27: No. | B27: Unidad | D27: Tema | F27: Sub Tema
A28: 1 | B28: =IFERROR(__xludf.DUMMYFUNCTION("FILTER('Diseño'!D:D,'Diseño'!H:H=$C$5)"),1.0) -> 1 | D28: =IFERROR(__xludf.DUMMYFUNCTION("FILTER('Diseño'!E:E,'Diseño'!H:H=$C$5)"),"Análisis Semántico") -> Análisis Semántico | F28: =IFERROR(__xludf.DUMMYFUNCTION("FILTER('Diseño'!F:F,'Diseño'!H:H=$C$5)"),"Atributos Sintetizados y Heredados") -> Atributos Sintetizados y Heredados
A29: 2 | B29: =IFERROR(__xludf.DUMMYFUNCTION("""COMPUTED_VALUE"""),1.0) -> 1 | D29: =IFERROR(__xludf.DUMMYFUNCTION("""COMPUTED_VALUE"""),"Análisis Semántico") -> Análisis Semántico | F29: =IFERROR(__xludf.DUMMYFUNCTION("""COMPUTED_VALUE"""),"Alcance y Tabla de Símbolos") -> Alcance y Tabla de Símbolos
A30: 3 | B30: =IFERROR(__xludf.DUMMYFUNCTION("""COMPUTED_VALUE"""),1.0) -> 1 | D30: =IFERROR(__xludf.DUMMYFUNCTION("""COMPUTED_VALUE"""),"Análisis Semántico") -> Análisis Semántico | F30: =IFERROR(__xludf.DUMMYFUNCTION("""COMPUTED_VALUE"""),"Validación de Tipos") -> Validación de Tipos
A31: 4 | B31: =IFERROR(__xludf.DUMMYFUNCTION("""COMPUTED_VALUE"""),1.0) -> 1 | D31: =IFERROR(__xludf.DUMMYFUNCTION("""COMPUTED_VALUE"""),"Análisis Semántico") -> Análisis Semántico | F31: =IFERROR(__xludf.DUMMYFUNCTION("""COMPUTED_VALUE"""),"Entornos") -> Entornos
A32: 5
A33: 6
A34: 7
A36: 2.2 Recursos Educativos
A38: Tipo de Recurso a utilizar | B38: Tipo | C38: Valor maximo recomendado en Minutos | D38: Tiempo Aproximado ( unicamente el valor de minutos ) | I38: Validacion
A39: Presentacion | B39: Obligatorio | C39: 30 | D39: 20 | I39: =IF(D39<=C39,"Correcto", "Corregir") -> Correcto
A40: Video | B40: Obligatorio | C40: 6 | I40: =IF(D40<=C40,"Correcto", "Corregir") -> Correcto
A41: Lectura | B41: Optativo | C41: 10 | I41: =IF(D41<=C41,"Correcto", "Corregir") -> Correcto
A42: Ejercicio Demostrativo | B42: Obligatorio | C42: 30 | D42: 40 | I42: =IF(D42<=C42,"Correcto", "Corregir") -> Corregir
A44: 3. Área de Habilidades (Saber Hacer) | G44: Tiempo Aproximado | H44: =B50 -> 30
G45: Tiene que estar en un rango de 30 a 50 minutos
A46: Actividad 1 (Obligatoria)
A47: Competencia que predomina en la actividad | B47: Analiza la semántica de un lenguaje de programación mediante la validación de tipos, alcance y estructuras de control para determinar la corrección de expresiones y sentencias
A48: Tipo de Actividad | B48: Ejercicio practico
A49: Ponderación
A50: Tiempo Aproximado | B50: 30
...

Sheet S.4
B2: Diseño de la Sesión de Laboratorio
B4: Curso | C4: ='Diseño'!C4 -> 781 - Organización de Lenguajes y Compiladores 2
B5: Semana | C5: 4
B6: Tiempo | C6: =H10+H21+H44+H68 -> 100
B7: Ponderación | C7: =B49+B60 -> 0
B8: Validación de Tiempo | C8: =IF(H44<=0, "❌ ERROR: La Actividad 1 debe tener un tiempo mayor a 0.", IF(H21>60, "❌ ERROR: El 'Área de Conocimiento' no puede exceder los 60 min.", IF(C6<100, "❌ ERROR: El tiempo total debe ser de al menos 100 min.", "✅ VALIDACIÓN CORRECTA"))) -> ✅ VALIDACIÓN CORRECTA
A10: 1. Área Actitudinal (Saber Ser) | G10: Tiempo Aproximado | H10: =B13 -> 5
G11: Tiene que estar en un rango de 3 a 5 minutos
A12: Nombre del Valor | B12: Ética en la Gestión de Errores y Robustez
A13: Tiempo Aproximado | B13: 5
A14: Descripcion
A15: Se refiere a la honestidad y compromiso del desarrollador por gestionar los fallos de manera que el sistema sea resiliente. Implica diseñar software que priorice la seguridad del usuario ante entradas inesperadas, garantizando una operación estable, transparente y confiable.
A17: Como se relaciona con los conocimientos de la sesion y se aplicaria
A18: En el contexto de Tipado Dinámico y Recuperación de Errores, este valor se aplica al diseñar mecanismos que manejen excepciones de forma clara. La robustez técnica asegura que el compilador proporcione una guía honesta al programador para corregir su código sin comprometer la integridad del sistema.
A21: 2. Área Conocimiento (Saber) | G21: Tiempo Aproximado | H21: =SUM(D39:H42) -> 60
G22: No puede exceder los 60 minutos
A23: Competencia a desarrollar | B23: Analiza la semántica de un lenguaje de programación mediante la validación de tipos, alcance y estructuras de control para determinar la corrección de expresiones y sentencias
A24: Competencia a desarrollar
A26: 2.1 Contenido
A27: No. | B27: Unidad | D27: Tema | F27: Sub Tema
A28: 1 | B28: =IFERROR(__xludf.DUMMYFUNCTION("FILTER('Diseño'!D:D,'Diseño'!H:H=$C$5)"),1.0) -> 1 | D28: =IFERROR(__xludf.DUMMYFUNCTION("FILTER('Diseño'!E:E,'Diseño'!H:H=$C$5)"),"Análisis Semántico") -> Análisis Semántico | F28: =IFERROR(__xludf.DUMMYFUNCTION("FILTER('Diseño'!F:F,'Diseño'!H:H=$C$5)"),"Tipado Dinámico") -> Tipado Dinámico
A29: 2 | B29: =IFERROR(__xludf.DUMMYFUNCTION("""COMPUTED_VALUE"""),1.0) -> 1 | D29: =IFERROR(__xludf.DUMMYFUNCTION("""COMPUTED_VALUE"""),"Análisis Semántico") -> Análisis Semántico | F29: =IFERROR(__xludf.DUMMYFUNCTION("""COMPUTED_VALUE"""),"Expresiones y Sentencias") -> Expresiones y Sentencias
A30: 3 | B30: =IFERROR(__xludf.DUMMYFUNCTION("""COMPUTED_VALUE"""),1.0) -> 1 | D30: =IFERROR(__xludf.DUMMYFUNCTION("""COMPUTED_VALUE"""),"Análisis Semántico") -> Análisis Semántico | F30: =IFERROR(__xludf.DUMMYFUNCTION("""COMPUTED_VALUE"""),"Estructuras de Control") -> Estructuras de Control
A31: 4 | B31: =IFERROR(__xludf.DUMMYFUNCTION("""COMPUTED_VALUE"""),1.0) -> 1 | D31: =IFERROR(__xludf.DUMMYFUNCTION("""COMPUTED_VALUE"""),"Análisis Semántico") -> Análisis Semántico | F31: =IFERROR(__xludf.DUMMYFUNCTION("""COMPUTED_VALUE"""),"Recuperación de Errores") -> Recuperación de Errores
A32: 5
A33: 6
A34: 7
A36: 2.2 Recursos Educativos
A38: Tipo de Recurso a utilizar | B38: Tipo | C38: Valor maximo recomendado en Minutos | D38: Tiempo Aproximado ( unicamente el valor de minutos ) | I38: Validacion
A39: Presentacion | B39: Obligatorio | C39: 30 | D39: 20 | I39: =IF(D39<=C39,"Correcto", "Corregir") -> Correcto
A40: Video | B40: Obligatorio | C40: 6 | I40: =IF(D40<=C40,"Correcto", "Corregir") -> Correcto
A41: Lectura | B41: Optativo | C41: 10 | I41: =IF(D41<=C41,"Correcto", "Corregir") -> Correcto
A42: Ejercicio Demostrativo | B42: Obligatorio | C42: 30 | D42: 40 | I42: =IF(D42<=C42,"Correcto", "Corregir") -> Corregir
A44: 3. Área de Habilidades (Saber Hacer) | G44: Tiempo Aproximado | H44: =B50 -> 30
G45: Tiene que estar en un rango de 30 a 50 minutos
A46: Actividad 1 (Obligatoria)
A47: Competencia que predomina en la actividad | B47: Analiza la semántica de un lenguaje de programación mediante la validación de tipos, alcance y estructuras de control para determinar la corrección de expresiones y sentencias
A48: Tipo de Actividad | B48: Ejercicio practico
A49: Ponderación | B49: 0
A50: Tiempo Aproximado | B50: 30
...

Sheet S.5
B2: Diseño de la Sesión de Laboratorio
B4: Curso | C4: ='Diseño'!C4 -> 781 - Organización de Lenguajes y Compiladores 2
B5: Semana | C5: 5
B6: Tiempo | C6: =H10+H21+H44+H68 -> 100
B7: Ponderación | C7: =B49+B60 -> 0
B8: Validación de Tiempo | C8: =IF(H44<=0, "❌ ERROR: La Actividad 1 debe tener un tiempo mayor a 0.", IF(H21>60, "❌ ERROR: El 'Área de Conocimiento' no puede exceder los 60 min.", IF(C6<100, "❌ ERROR: El tiempo total debe ser de al menos 100 min.", "✅ VALIDACIÓN CORRECTA"))) -> ✅ VALIDACIÓN CORRECTA
A10: 1. Área Actitudinal (Saber Ser) | G10: Tiempo Aproximado | H10: 5
G11: Tiene que estar en un rango de 3 a 5 minutos
A12: Nombre del Valor | B12: Ética del Alcance
A13: Tiempo Aproximado
A14: Descripcion
A15: Mantener el uso de variables dentro de su contexto lógico y justo.
A17: Como se relaciona con los conocimientos de la sesion y se aplicaria
A18: Saber reconocer hasta donde puede afectar un cambio es importante tanto en el ambito del manejo de funciones como en la vida profesional.
A21: 2. Área Conocimiento (Saber) | G21: Tiempo Aproximado | H21: 55
G22: No puede exceder los 60 minutos
A23: Competencia a desarrollar | B23: Evalua la representacion semantica de funciones, y objetos mediante el análisis de alcance, tipos y tabla de simbolos para determinar su correcta representación en interpretes y compiladores
A24: Competencia a desarrollar | B24: Analiza la semántica de un lenguaje de programación mediante la validación de tipos, alcance y estructuras de control para determinar la corrección de expresiones y sentencias
A26: 2.1 Contenido
A27: No. | B27: Unidad | D27: Tema | F27: Sub Tema
A28: 1 | B28: 2 | D28: Funciones | F28: Funciones y sus tipos
A29: 2 | B29: 2 | D29: Funciones | F29: Parametros y Argumentos de una función
A30: 3 | B30: 2 | D30: Funciones | F30: Hoisting
A31: 4 | B31: 2 | D31: Funciones | F31: Callstack
A32: 5 | B32: 2 | D32: Funciones | F32: Closures
A33: 6
A34: 7
A36: 2.2 Recursos Educativos
A38: Tipo de Recurso a utilizar | B38: Tipo | C38: Valor maximo recomendado en Minutos | D38: Tiempo Aproximado ( unicamente el valor de minutos ) | I38: Validacion
A39: Presentacion | B39: Obligatorio | C39: 30 | D39: 30 | I39: =IF(D39<=C39,"Correcto", "Corregir") -> Correcto
A40: Video | B40: Obligatorio | C40: 6 | I40: =IF(D40<=C40,"Correcto", "Corregir") -> Correcto
A41: Lectura | B41: Optativo | C41: 10 | I41: =IF(D41<=C41,"Correcto", "Corregir") -> Correcto
A42: Ejercicio Demostrativo | B42: Obligatorio | C42: 30 | D42: 30 | I42: =IF(D42<=C42,"Correcto", "Corregir") -> Correcto
A44: 3. Área de Habilidades (Saber Hacer) | G44: Tiempo Aproximado | H44: 30
G45: Tiene que estar en un rango de 30 a 50 minutos
A46: Actividad 1 (Obligatoria)
A47: Competencia que predomina en la actividad | B47: Evalua la representacion semantica de funciones, y objetos mediante el análisis de alcance, tipos y tabla de simbolos para determinar su correcta representación en interpretes y compiladores
A48: Tipo de Actividad | B48: Ejercicio practico
A49: Ponderación | B49: 0
A50: Tiempo Aproximado | B50: 30
...

Sheet S.6
B2: Diseño de la Sesión de Laboratorio
B4: Curso | C4: ='Diseño'!C4 -> 781 - Organización de Lenguajes y Compiladores 2
B5: Semana | C5: 6
B6: Tiempo | C6: =H10+H21+H44+H68 -> 100
B7: Ponderación | C7: =B49+B60 -> 0
B8: Validación de Tiempo | C8: =IF(H44<=0, "❌ ERROR: La Actividad 1 debe tener un tiempo mayor a 0.", IF(H21>60, "❌ ERROR: El 'Área de Conocimiento' no puede exceder los 60 min.", IF(C6<100, "❌ ERROR: El tiempo total debe ser de al menos 100 min.", "✅ VALIDACIÓN CORRECTA"))) -> ✅ VALIDACIÓN CORRECTA
A10: 1. Área Actitudinal (Saber Ser) | G10: Tiempo Aproximado | H10: 5
G11: Tiene que estar en un rango de 3 a 5 minutos
A12: Nombre del Valor | B12: Precisión
A13: Tiempo Aproximado
A14: Descripcion
A15: ya que al aplicar técnicas de optimización y análisis de código, se requiere atención a los detalles para lograr mejoras reales y evitar errores.
A17: Como se relaciona con los conocimientos de la sesion y se aplicaria
A18: El control preciso de las relaciones y los tipos al momento de manejar herencia entre diversos objetos es importante para asegurar un sistema de tipos estable y potente.
A21: 2. Área Conocimiento (Saber) | G21: Tiempo Aproximado | H21: 40
G22: No puede exceder los 60 minutos
A23: Competencia a desarrollar | B23: Evalua la representacion semantica de funciones y objetos mediante el análisis de alcance, tipos y tabla de simbolos para determinar su correcta representación en interpretes y compiladores
A24: Competencia a desarrollar | B24: Analiza la semántica de un lenguaje de programación mediante la validación de tipos, alcance y estructuras de control para determinar la corrección de expresiones y sentencias
A26: 2.1 Contenido
A27: No. | B27: Unidad | D27: Tema | F27: Sub Tema
A28: 1 | B28: =IFERROR(__xludf.DUMMYFUNCTION("FILTER('Diseño'!D:D,'Diseño'!H:H=$C$5)"),2.0) -> 2 | D28: =IFERROR(__xludf.DUMMYFUNCTION("FILTER('Diseño'!E:E,'Diseño'!H:H=$C$5)"),"Programación Orientada a Objetos") -> Programación Orientada a Objetos | F28: =IFERROR(__xludf.DUMMYFUNCTION("FILTER('Diseño'!F:F,'Diseño'!H:H=$C$5)"),"Clases y Objetos") -> Clases y Objetos
A29: 2 | B29: =IFERROR(__xludf.DUMMYFUNCTION("""COMPUTED_VALUE"""),2.0) -> 2 | D29: =IFERROR(__xludf.DUMMYFUNCTION("""COMPUTED_VALUE"""),"Programación Orientada a Objetos") -> Programación Orientada a Objetos | F29: =IFERROR(__xludf.DUMMYFUNCTION("""COMPUTED_VALUE"""),"Prototipos") -> Prototipos
A30: 3 | B30: =IFERROR(__xludf.DUMMYFUNCTION("""COMPUTED_VALUE"""),2.0) -> 2 | D30: =IFERROR(__xludf.DUMMYFUNCTION("""COMPUTED_VALUE"""),"Programación Orientada a Objetos") -> Programación Orientada a Objetos | F30: =IFERROR(__xludf.DUMMYFUNCTION("""COMPUTED_VALUE"""),"Constructores") -> Constructores
A31: 4 | B31: =IFERROR(__xludf.DUMMYFUNCTION("""COMPUTED_VALUE"""),2.0) -> 2 | D31: =IFERROR(__xludf.DUMMYFUNCTION("""COMPUTED_VALUE"""),"Programación Orientada a Objetos") -> Programación Orientada a Objetos | F31: =IFERROR(__xludf.DUMMYFUNCTION("""COMPUTED_VALUE"""),"Sobrecarga de Métodos") -> Sobrecarga de Métodos
A32: 5 | B32: =IFERROR(__xludf.DUMMYFUNCTION("""COMPUTED_VALUE"""),2.0) -> 2 | D32: =IFERROR(__xludf.DUMMYFUNCTION("""COMPUTED_VALUE"""),"Programación Orientada a Objetos") -> Programación Orientada a Objetos | F32: =IFERROR(__xludf.DUMMYFUNCTION("""COMPUTED_VALUE"""),"Estructura en Memoria") -> Estructura en Memoria
A33: 6
A34: 7
A36: 2.2 Recursos Educativos
A38: Tipo de Recurso a utilizar | B38: Tipo | C38: Valor maximo recomendado en Minutos | D38: Tiempo Aproximado ( unicamente el valor de minutos ) | I38: Validacion
A39: Presentacion | B39: Obligatorio | C39: 30 | D39: 25 | I39: =IF(D39<=C39,"Correcto", "Corregir") -> Correcto
A40: Video | B40: Obligatorio | C40: 6 | I40: =IF(D40<=C40,"Correcto", "Corregir") -> Correcto
A41: Lectura | B41: Optativo | C41: 10 | I41: =IF(D41<=C41,"Correcto", "Corregir") -> Correcto
A42: Ejercicio Demostrativo | B42: Obligatorio | C42: 30 | D42: 15 | I42: =IF(D42<=C42,"Correcto", "Corregir") -> Correcto
A44: 3. Área de Habilidades (Saber Hacer) | G44: Tiempo Aproximado | H44: 45
G45: Tiene que estar en un rango de 30 a 50 minutos
A46: Actividad 1 (Obligatoria)
A47: Competencia que predomina en la actividad | B47: Evalua la representacion semantica de funciones, y objetos mediante el análisis de alcance, tipos y tabla de simbolos para determinar su correcta representación en interpretes y compiladores
A48: Tipo de Actividad | B48: otros
A49: Ponderación | B49: 0
A50: Tiempo Aproximado
...

Sheet S.7
B2: Diseño de la Sesión de Laboratorio
B4: Curso | C4: ='Diseño'!C4 -> 781 - Organización de Lenguajes y Compiladores 2
B5: Semana | C5: 7
B6: Tiempo | C6: =H10+H21+H44+H68 -> 100
B7: Ponderación | C7: =B49+B60 -> 0
B8: Validación de Tiempo | C8: =IF(H44<=0, "❌ ERROR: La Actividad 1 debe tener un tiempo mayor a 0.", IF(H21>60, "❌ ERROR: El 'Área de Conocimiento' no puede exceder los 60 min.", IF(C6<100, "❌ ERROR: El tiempo total debe ser de al menos 100 min.", "✅ VALIDACIÓN CORRECTA"))) -> ✅ VALIDACIÓN CORRECTA
A10: 1. Área Actitudinal (Saber Ser) | G10: Tiempo Aproximado | H10: 5
G11: Tiene que estar en un rango de 3 a 5 minutos
A12: Nombre del Valor | B12: Rigor
A13: Tiempo Aproximado
A14: Descripcion
A15: porque se trabaja con conceptos técnicos de bajo nivel, donde la precisión y estructura lógica son clave, especialmente en temas como ensamblador o representación en memoria.
A17: Como se relaciona con los conocimientos de la sesion y se aplicaria
A18: Un manejo cuidadoso de las equivalencias al traducir evitara problemas a futuro y simplificara la opitmizacion del codigo 3 direcciones a futuro.
A21: 2. Área Conocimiento (Saber) | G21: Tiempo Aproximado | H21: 40
G22: No puede exceder los 60 minutos
A23: Competencia a desarrollar | B23: Analiza las equivalencias sintácticas y semánticas de un lenguaje de alto nivel mediante el mapeo de construcciones a instrucciones de Representación Intermedia tales como C3D, cuádruplas o Bytecode.
A24: Competencia a desarrollar
A26: 2.1 Contenido
A27: No. | B27: Unidad | D27: Tema | F27: Sub Tema
A28: 1 | B28: =IFERROR(__xludf.DUMMYFUNCTION("FILTER('Diseño'!D:D,'Diseño'!H:H=$C$5)"),3.0) -> 3 | D28: =IFERROR(__xludf.DUMMYFUNCTION("FILTER('Diseño'!E:E,'Diseño'!H:H=$C$5)"),"Representaciones intermedias y generación de código") -> Representaciones intermedias y generación de código | F28: =IFERROR(__xludf.DUMMYFUNCTION("FILTER('Diseño'!F:F,'Diseño'!H:H=$C$5)"),"Codigo de 3 direcciones") -> Codigo de 3 direcciones
A29: 2 | B29: =IFERROR(__xludf.DUMMYFUNCTION("""COMPUTED_VALUE"""),3.0) -> 3 | D29: =IFERROR(__xludf.DUMMYFUNCTION("""COMPUTED_VALUE"""),"Representaciones intermedias y generación de código") -> Representaciones intermedias y generación de código | F29: =IFERROR(__xludf.DUMMYFUNCTION("""COMPUTED_VALUE"""),"Bytecode") -> Bytecode
A30: 3 | B30: =IFERROR(__xludf.DUMMYFUNCTION("""COMPUTED_VALUE"""),3.0) -> 3 | D30: =IFERROR(__xludf.DUMMYFUNCTION("""COMPUTED_VALUE"""),"Representaciones intermedias y generación de código") -> Representaciones intermedias y generación de código | F30: =IFERROR(__xludf.DUMMYFUNCTION("""COMPUTED_VALUE"""),"Assembly: Risc-V y ARM64") -> Assembly: Risc-V y ARM64
A31: 4 | B31: =IFERROR(__xludf.DUMMYFUNCTION("""COMPUTED_VALUE"""),3.0) -> 3 | D31: =IFERROR(__xludf.DUMMYFUNCTION("""COMPUTED_VALUE"""),"Representaciones intermedias y generación de código") -> Representaciones intermedias y generación de código | F31: =IFERROR(__xludf.DUMMYFUNCTION("""COMPUTED_VALUE"""),"Enteros") -> Enteros
A32: 5 | B32: =IFERROR(__xludf.DUMMYFUNCTION("""COMPUTED_VALUE"""),3.0) -> 3 | D32: =IFERROR(__xludf.DUMMYFUNCTION("""COMPUTED_VALUE"""),"Representaciones intermedias y generación de código") -> Representaciones intermedias y generación de código | F32: =IFERROR(__xludf.DUMMYFUNCTION("""COMPUTED_VALUE"""),"Punto Flotante") -> Punto Flotante
A33: 6 | B33: =IFERROR(__xludf.DUMMYFUNCTION("""COMPUTED_VALUE"""),3.0) -> 3 | D33: =IFERROR(__xludf.DUMMYFUNCTION("""COMPUTED_VALUE"""),"Representaciones intermedias y generación de código") -> Representaciones intermedias y generación de código | F33: =IFERROR(__xludf.DUMMYFUNCTION("""COMPUTED_VALUE"""),"Char y Strings") -> Char y Strings
A34: 7
A36: 2.2 Recursos Educativos
A38: Tipo de Recurso a utilizar | B38: Tipo | C38: Valor maximo recomendado en Minutos | D38: Tiempo Aproximado ( unicamente el valor de minutos ) | I38: Validacion
A39: Presentacion | B39: Obligatorio | C39: 30 | D39: 30 | I39: =IF(D39<=C39,"Correcto", "Corregir") -> Correcto
A40: Video | B40: Obligatorio | C40: 6 | I40: =IF(D40<=C40,"Correcto", "Corregir") -> Correcto
A41: Lectura | B41: Optativo | C41: 10 | I41: =IF(D41<=C41,"Correcto", "Corregir") -> Correcto
A42: Ejercicio Demostrativo | B42: Obligatorio | C42: 30 | D42: 10 | I42: =IF(D42<=C42,"Correcto", "Corregir") -> Correcto
A44: 3. Área de Habilidades (Saber Hacer) | G44: Tiempo Aproximado | H44: 45
G45: Tiene que estar en un rango de 30 a 50 minutos
A46: Actividad 1 (Obligatoria)
A47: Competencia que predomina en la actividad | B47: Analiza las equivalencias sintácticas y semánticas de un lenguaje de alto nivel mediante el mapeo de construcciones a instrucciones de Representación Intermedia tales como C3D, cuádruplas o Bytecode.
A48: Tipo de Actividad | B48: Ejercicio practico
A49: Ponderación | B49: 0
A50: Tiempo Aproximado
...

Sheet S.8
B2: Diseño de la Sesión de Laboratorio
B4: Curso | C4: ='Diseño'!C4 -> 781 - Organización de Lenguajes y Compiladores 2
B5: Semana | C5: 8
B6: Tiempo | C6: =H10+H21+H44+H68 -> 100
B7: Ponderación | C7: =B49+B60 -> 0
B8: Validación de Tiempo | C8: =IF(H44<=0, "❌ ERROR: La Actividad 1 debe tener un tiempo mayor a 0.", IF(H21>60, "❌ ERROR: El 'Área de Conocimiento' no puede exceder los 60 min.", IF(C6<100, "❌ ERROR: El tiempo total debe ser de al menos 100 min.", "✅ VALIDACIÓN CORRECTA"))) -> ✅ VALIDACIÓN CORRECTA
A10: 1. Área Actitudinal (Saber Ser) | G10: Tiempo Aproximado | H10: 5
G11: Tiene que estar en un rango de 3 a 5 minutos
A12: Nombre del Valor
A13: Tiempo Aproximado | B13: Responsabilidad computacional
A14: Descripcion
A15: El uso correcto de las tablas de símbolos ayudan a la eficiencia del programa
A17: Como se relaciona con los conocimientos de la sesion y se aplicaria
A18: El uso correcto de la memoria es importante para garantizar la seguridad de las aplicaciones, un manejo responsable evitara posibles exploits y peligros ocultos.
A21: 2. Área Conocimiento (Saber) | G21: Tiempo Aproximado | H21: 40
G22: No puede exceder los 60 minutos
A23: Competencia a desarrollar | B23: Analiza las equivalencias sintácticas y semánticas de un lenguaje de alto nivel mediante el mapeo de construcciones a instrucciones de Representación Intermedia tales como C3D, cuádruplas o Bytecode.
A24: Competencia a desarrollar
A26: 2.1 Contenido
A27: No. | B27: Unidad | D27: Tema | F27: Sub Tema
A28: 1 | B28: =IFERROR(__xludf.DUMMYFUNCTION("FILTER('Diseño'!D:D,'Diseño'!H:H=$C$5)"),3.0) -> 3 | D28: =IFERROR(__xludf.DUMMYFUNCTION("FILTER('Diseño'!E:E,'Diseño'!H:H=$C$5)"),"Entornos y memoria en un compilador") -> Entornos y memoria en un compilador | F28: =IFERROR(__xludf.DUMMYFUNCTION("FILTER('Diseño'!F:F,'Diseño'!H:H=$C$5)"),"Tabla de Símbolos") -> Tabla de Símbolos
A29: 2 | B29: =IFERROR(__xludf.DUMMYFUNCTION("""COMPUTED_VALUE"""),3.0) -> 3 | D29: =IFERROR(__xludf.DUMMYFUNCTION("""COMPUTED_VALUE"""),"Entornos y memoria en un compilador") -> Entornos y memoria en un compilador | F29: =IFERROR(__xludf.DUMMYFUNCTION("""COMPUTED_VALUE"""),"Stack, Heap y punteros") -> Stack, Heap y punteros
A30: 3 | B30: =IFERROR(__xludf.DUMMYFUNCTION("""COMPUTED_VALUE"""),3.0) -> 3 | D30: =IFERROR(__xludf.DUMMYFUNCTION("""COMPUTED_VALUE"""),"Entornos y memoria en un compilador") -> Entornos y memoria en un compilador | F30: =IFERROR(__xludf.DUMMYFUNCTION("""COMPUTED_VALUE"""),"Resolución de variables") -> Resolución de variables
A31: 4 | B31: =IFERROR(__xludf.DUMMYFUNCTION("""COMPUTED_VALUE"""),3.0) -> 3 | D31: =IFERROR(__xludf.DUMMYFUNCTION("""COMPUTED_VALUE"""),"Entornos y memoria en un compilador") -> Entornos y memoria en un compilador | F31: =IFERROR(__xludf.DUMMYFUNCTION("""COMPUTED_VALUE"""),"Estructuras de Control en C3D (Etiquetas y Saltos)") -> Estructuras de Control en C3D (Etiquetas y Saltos)
A32: 5
A33: 6
A34: 7
A36: 2.2 Recursos Educativos
A38: Tipo de Recurso a utilizar | B38: Tipo | C38: Valor maximo recomendado en Minutos | D38: Tiempo Aproximado ( unicamente el valor de minutos ) | I38: Validacion
A39: Presentacion | B39: Obligatorio | C39: 30 | D39: 15 | I39: =IF(D39<=C39,"Correcto", "Corregir") -> Correcto
A40: Video | B40: Obligatorio | C40: 6 | I40: =IF(D40<=C40,"Correcto", "Corregir") -> Correcto
A41: Lectura | B41: Optativo | C41: 10 | I41: =IF(D41<=C41,"Correcto", "Corregir") -> Correcto
A42: Ejercicio Demostrativo | B42: Obligatorio | C42: 30 | D42: 25 | I42: =IF(D42<=C42,"Correcto", "Corregir") -> Correcto
A44: 3. Área de Habilidades (Saber Hacer) | G44: Tiempo Aproximado | H44: 45
G45: Tiene que estar en un rango de 30 a 50 minutos
A46: Actividad 1 (Obligatoria)
A47: Competencia que predomina en la actividad | B47: Analiza las equivalencias sintácticas y semánticas de un lenguaje de alto nivel mediante el mapeo de construcciones a instrucciones de Representación Intermedia tales como C3D, cuádruplas o Bytecode.
A48: Tipo de Actividad | B48: otros
A49: Ponderación | B49: 0
A50: Tiempo Aproximado
...

Sheet S.9
B2: Diseño de la Sesión de Laboratorio
B4: Curso | C4: ='Diseño'!C4 -> 781 - Organización de Lenguajes y Compiladores 2
B5: Semana | C5: 9
B6: Tiempo | C6: =H10+H21+H44+H68 -> 110
B7: Ponderación | C7: =B49+B60 -> 0
B8: Validación de Tiempo | C8: =IF(H44<=0, "❌ ERROR: La Actividad 1 debe tener un tiempo mayor a 0.", IF(H21>60, "❌ ERROR: El 'Área de Conocimiento' no puede exceder los 60 min.", IF((H10+H21+H44)<100, "❌ ERROR: El tiempo total debe ser de al menos 100 min.", "✅ VALIDACIÓN CORRECTA"))) -> ✅ VALIDACIÓN CORRECTA
A10: 1. Área Actitudinal (Saber Ser) | G10: Tiempo Aproximado | H10: 5
G11: Tiene que estar en un rango de 3 a 5 minutos
A12: Nombre del Valor | B12: Rigor técnico
A13: Tiempo Aproximado
A14: Descripcion
A15: La traducción de funciones e instrucciones ocupa la mayor parte de complejidad en un compilador por lo que mejora su uso
A17: Como se relaciona con los conocimientos de la sesion y se aplicaria
A21: 2. Área Conocimiento (Saber) | G21: Tiempo Aproximado | H21: 60
G22: No puede exceder los 60 minutos
A23: Competencia a desarrollar | B23: Generar un compilador utilizando como representación intermedia lenguajes ensambladores como RISC-V o Aarch64
A24: Competencia a desarrollar
A26: 2.1 Contenido
A27: No. | B27: Unidad | D27: Tema | F27: Sub Tema
A28: 1 | B28: =IFERROR(__xludf.DUMMYFUNCTION("FILTER('Diseño'!D:D,'Diseño'!H:H=$C$5)"),3.0) -> 3 | D28: =IFERROR(__xludf.DUMMYFUNCTION("FILTER('Diseño'!E:E,'Diseño'!H:H=$C$5)"),"Entornos y memoria en un compilador") -> Entornos y memoria en un compilador | F28: =IFERROR(__xludf.DUMMYFUNCTION("FILTER('Diseño'!F:F,'Diseño'!H:H=$C$5)"),"Memoria en tiempo de ejecución") -> Memoria en tiempo de ejecución
A29: 2 | B29: =IFERROR(__xludf.DUMMYFUNCTION("""COMPUTED_VALUE"""),3.0) -> 3 | D29: =IFERROR(__xludf.DUMMYFUNCTION("""COMPUTED_VALUE"""),"Entornos y memoria en un compilador") -> Entornos y memoria en un compilador | F29: =IFERROR(__xludf.DUMMYFUNCTION("""COMPUTED_VALUE"""),"Descriptores de registros y direcciones") -> Descriptores de registros y direcciones
A30: 3 | B30: =IFERROR(__xludf.DUMMYFUNCTION("""COMPUTED_VALUE"""),3.0) -> 3 | D30: =IFERROR(__xludf.DUMMYFUNCTION("""COMPUTED_VALUE"""),"Entornos y memoria en un compilador") -> Entornos y memoria en un compilador | F30: =IFERROR(__xludf.DUMMYFUNCTION("""COMPUTED_VALUE"""),"Registros de activación") -> Registros de activación
A31: 4 | B31: =IFERROR(__xludf.DUMMYFUNCTION("""COMPUTED_VALUE"""),3.0) -> 3 | D31: =IFERROR(__xludf.DUMMYFUNCTION("""COMPUTED_VALUE"""),"Entornos y memoria en un compilador") -> Entornos y memoria en un compilador | F31: =IFERROR(__xludf.DUMMYFUNCTION("""COMPUTED_VALUE"""),"Paso de argumentos") -> Paso de argumentos
A32: 5
A33: 6
A34: 7
A36: 2.2 Recursos Educativos
A38: Tipo de Recurso a utilizar | B38: Tipo | C38: Valor maximo recomendado en Minutos | D38: Tiempo Aproximado ( unicamente el valor de minutos ) | I38: Validacion
A39: Presentacion | B39: Obligatorio | C39: 30 | D39: 30 | I39: =IF(D39<=C39,"Correcto", "Corregir") -> Correcto
A40: Video | B40: Obligatorio | C40: 6 | I40: =IF(D40<=C40,"Correcto", "Corregir") -> Correcto
A41: Lectura | B41: Optativo | C41: 10 | I41: =IF(D41<=C41,"Correcto", "Corregir") -> Correcto
A42: Ejercicio Demostrativo | B42: Obligatorio | C42: 30 | D42: 20 | I42: =IF(D42<=C42,"Correcto", "Corregir") -> Correcto
A44: 3. Área de Habilidades (Saber Hacer) | G44: Tiempo Aproximado | H44: 35
G45: Tiene que estar en un rango de 30 a 50 minutos
A46: Actividad 1 (Obligatoria)
A47: Competencia que predomina en la actividad | B47: Generar un compilador utilizando como representación intermedia lenguajes ensambladores como RISC-V o Aarch64
A48: Tipo de Actividad | B48: Ejercicio practico
A49: Ponderación | B49: 0
A50: Tiempo Aproximado
A51: Coloca el tiempo que usar en la actividad, un tiempo sugerido 30 minutos
...

Sheet S.10
B2: Diseño de la Sesión de Laboratorio
B4: Curso | C4: ='Diseño'!C4 -> 781 - Organización de Lenguajes y Compiladores 2
B5: Semana | C5: 10
B6: Tiempo | C6: =H10+H21+H44+H68 -> 110
B7: Ponderación | C7: =B49+B60 -> 0
B8: Validación de Tiempo | C8: =IF(H44<=0, "❌ ERROR: La Actividad 1 debe tener un tiempo mayor a 0.", IF(H21>60, "❌ ERROR: El 'Área de Conocimiento' no puede exceder los 60 min.", IF((H10+H21+H44)<100, "❌ ERROR: El tiempo total debe ser de al menos 100 min.", "✅ VALIDACIÓN CORRECTA"))) -> ✅ VALIDACIÓN CORRECTA
A10: 1. Área Actitudinal (Saber Ser) | G10: Tiempo Aproximado | H10: 5
G11: Tiene que estar en un rango de 3 a 5 minutos
A12: Nombre del Valor | B12: Responsabilidad computacional
A13: Tiempo Aproximado
A14: Descripcion
A15: El uso de la memoria permite que los programas generados por el compilador tengan un rendimiento adecuado
A17: Como se relaciona con los conocimientos de la sesion y se aplicaria
A21: 2. Área Conocimiento (Saber) | G21: Tiempo Aproximado | H21: 60
G22: No puede exceder los 60 minutos
A23: Competencia a desarrollar | B23: Generar un compilador utilizando como representación intermedia lenguajes ensambladores como RISC-V o Aarch64
A24: Competencia a desarrollar
A26: 2.1 Contenido
A27: No. | B27: Unidad | D27: Tema | F27: Sub Tema
A28: 1 | B28: =IFERROR(__xludf.DUMMYFUNCTION("FILTER('Diseño'!D:D,'Diseño'!H:H=$C$5)"),3.0) -> 3 | D28: =IFERROR(__xludf.DUMMYFUNCTION("FILTER('Diseño'!E:E,'Diseño'!H:H=$C$5)"),"Entornos y memoria en un compilador") -> Entornos y memoria en un compilador | F28: =IFERROR(__xludf.DUMMYFUNCTION("FILTER('Diseño'!F:F,'Diseño'!H:H=$C$5)"),"Memoria heap en tiempo de ejecución") -> Memoria heap en tiempo de ejecución
A29: 2 | B29: =IFERROR(__xludf.DUMMYFUNCTION("""COMPUTED_VALUE"""),3.0) -> 3 | D29: =IFERROR(__xludf.DUMMYFUNCTION("""COMPUTED_VALUE"""),"Representaciones intermedias y generación de código") -> Representaciones intermedias y generación de código | F29: =IFERROR(__xludf.DUMMYFUNCTION("""COMPUTED_VALUE"""),"Arreglos y String, métodos de guardado") -> Arreglos y String, métodos de guardado
A30: 3 | B30: =IFERROR(__xludf.DUMMYFUNCTION("""COMPUTED_VALUE"""),3.0) -> 3 | D30: =IFERROR(__xludf.DUMMYFUNCTION("""COMPUTED_VALUE"""),"Representaciones intermedias y generación de código") -> Representaciones intermedias y generación de código | F30: =IFERROR(__xludf.DUMMYFUNCTION("""COMPUTED_VALUE"""),"Utilización de la pila para guardar punteros") -> Utilización de la pila para guardar punteros
A31: 4
A32: 5
A33: 6
A34: 7
A36: 2.2 Recursos Educativos
A38: Tipo de Recurso a utilizar | B38: Tipo | C38: Valor maximo recomendado en Minutos | D38: Tiempo Aproximado ( unicamente el valor de minutos ) | I38: Validacion
A39: Presentacion | B39: Obligatorio | C39: 30 | D39: 30 | I39: =IF(D39<=C39,"Correcto", "Corregir") -> Correcto
A40: Video | B40: Obligatorio | C40: 6 | I40: =IF(D40<=C40,"Correcto", "Corregir") -> Correcto
A41: Lectura | B41: Optativo | C41: 10 | I41: =IF(D41<=C41,"Correcto", "Corregir") -> Correcto
A42: Ejercicio Demostrativo | B42: Obligatorio | C42: 30 | D42: 30 | I42: =IF(D42<=C42,"Correcto", "Corregir") -> Correcto
A44: 3. Área de Habilidades (Saber Hacer) | G44: Tiempo Aproximado | H44: 35
G45: Tiene que estar en un rango de 30 a 50 minutos
A46: Actividad 1 (Obligatoria)
A47: Competencia que predomina en la actividad | B47: Generar un compilador utilizando como representación intermedia lenguajes ensambladores como RISC-V o Aarch64
A48: Tipo de Actividad | B48: Ejercicio practico
A49: Ponderación | B49: 0
A50: Tiempo Aproximado
A51: Coloca el tiempo que usar en la actividad, un tiempo sugerido 30 minutos
...

Sheet S.11
B2: Diseño de la Sesión de Laboratorio
B4: Curso | C4: ='Diseño'!C4 -> 781 - Organización de Lenguajes y Compiladores 2
B5: Semana | C5: 11
B6: Tiempo | C6: =H10+H21+H44+H68 -> 110
B7: Ponderación | C7: =B49+B60 -> 0
B8: Validación de Tiempo | C8: =IF(H44<=0, "❌ ERROR: La Actividad 1 debe tener un tiempo mayor a 0.", IF(H21>60, "❌ ERROR: El 'Área de Conocimiento' no puede exceder los 60 min.", IF((H10+H21+H44)<100, "❌ ERROR: El tiempo total debe ser de al menos 100 min.", "✅ VALIDACIÓN CORRECTA"))) -> ✅ VALIDACIÓN CORRECTA
A10: 1. Área Actitudinal (Saber Ser) | G10: Tiempo Aproximado | H10: 5
G11: Tiene que estar en un rango de 3 a 5 minutos
A12: Nombre del Valor | B12: Organización y estructura
A13: Tiempo Aproximado
A14: Descripcion
A15: El manejo de entornos y tabla de símbolos requiere una organización sistemática para gestionar correctamente el alcance de variables y sus valores.
A17: Como se relaciona con los conocimientos de la sesion y se aplicaria
A21: 2. Área Conocimiento (Saber) | G21: Tiempo Aproximado | H21: 60
G22: No puede exceder los 60 minutos
A23: Competencia a desarrollar | B23: Generar un compilador utilizando como representación intermedia lenguajes ensambladores como RISC-V o Aarch64
A24: Competencia a desarrollar
A26: 2.1 Contenido
A27: No. | B27: Unidad | D27: Tema | F27: Sub Tema
A28: 1 | B28: =IFERROR(__xludf.DUMMYFUNCTION("FILTER('Diseño'!D:D,'Diseño'!H:H=$C$5)"),3.0) -> 3 | D28: =IFERROR(__xludf.DUMMYFUNCTION("FILTER('Diseño'!E:E,'Diseño'!H:H=$C$5)"),"Entornos y memoria en un compilador") -> Entornos y memoria en un compilador | F28: =IFERROR(__xludf.DUMMYFUNCTION("FILTER('Diseño'!F:F,'Diseño'!H:H=$C$5)"),"Utilización del puntero link para funciones recursivas") -> Utilización del puntero link para funciones recursivas
A29: 2 | B29: =IFERROR(__xludf.DUMMYFUNCTION("""COMPUTED_VALUE"""),3.0) -> 3 | D29: =IFERROR(__xludf.DUMMYFUNCTION("""COMPUTED_VALUE"""),"Optimización de la generación de código") -> Optimización de la generación de código | F29: =IFERROR(__xludf.DUMMYFUNCTION("""COMPUTED_VALUE"""),"Métodos de optimización") -> Métodos de optimización
A30: 3 | B30: =IFERROR(__xludf.DUMMYFUNCTION("""COMPUTED_VALUE"""),3.0) -> 3 | D30: =IFERROR(__xludf.DUMMYFUNCTION("""COMPUTED_VALUE"""),"Optimización de la generación de código") -> Optimización de la generación de código | F30: =IFERROR(__xludf.DUMMYFUNCTION("""COMPUTED_VALUE"""),"Fases para optimizar en la creación del compilador") -> Fases para optimizar en la creación del compilador
A31: 4
A32: 5
A33: 6
A34: 7
A36: 2.2 Recursos Educativos
A38: Tipo de Recurso a utilizar | B38: Tipo | C38: Valor maximo recomendado en Minutos | D38: Tiempo Aproximado ( unicamente el valor de minutos ) | I38: Validacion
A39: Presentacion | B39: Obligatorio | C39: 30 | D39: 30 | I39: =IF(D39<=C39,"Correcto", "Corregir") -> Correcto
A40: Video | B40: Obligatorio | C40: 6 | I40: =IF(D40<=C40,"Correcto", "Corregir") -> Correcto
A41: Lectura | B41: Optativo | C41: 10 | I41: =IF(D41<=C41,"Correcto", "Corregir") -> Correcto
A42: Ejercicio Demostrativo | B42: Obligatorio | C42: 30 | D42: 30 | I42: =IF(D42<=C42,"Correcto", "Corregir") -> Correcto
A44: 3. Área de Habilidades (Saber Hacer) | G44: Tiempo Aproximado | H44: 35
G45: Tiene que estar en un rango de 30 a 50 minutos
A46: Actividad 1 (Obligatoria)
A47: Competencia que predomina en la actividad | B47: Generar un compilador utilizando como representación intermedia lenguajes ensambladores como RISC-V o Aarch64
A48: Tipo de Actividad | B48: Ejercicio practico
A49: Ponderación | B49: 0
A50: Tiempo Aproximado
A51: Coloca el tiempo que usar en la actividad, un tiempo sugerido 30 minutos
...

Sheet S.12
B2: Diseño de la Sesión de Laboratorio
B4: Curso | C4: ='Diseño'!C4 -> 781 - Organización de Lenguajes y Compiladores 2
B5: Semana | C5: 12
B6: Tiempo | C6: =H10+H21+H44+H68 -> 110
B7: Ponderación | C7: =B49+B60 -> 0
B8: Validación de Tiempo | C8: =IF(H44<=0, "❌ ERROR: La Actividad 1 debe tener un tiempo mayor a 0.", IF(H21>60, "❌ ERROR: El 'Área de Conocimiento' no puede exceder los 60 min.", IF((H10+H21+H44)<100, "❌ ERROR: El tiempo total debe ser de al menos 100 min.", "✅ VALIDACIÓN CORRECTA"))) -> ✅ VALIDACIÓN CORRECTA
A10: 1. Área Actitudinal (Saber Ser) | G10: Tiempo Aproximado | H10: 5
G11: Tiene que estar en un rango de 3 a 5 minutos
A12: Nombre del Valor | B12: Precisión
A13: Tiempo Aproximado
A14: Descripcion
A15: La optimización es el paso que nos permite corregir aquello generado en el proceso de compilación lo que permite que el resultado final siempre sea óptimo
A17: Como se relaciona con los conocimientos de la sesion y se aplicaria
A21: 2. Área Conocimiento (Saber) | G21: Tiempo Aproximado | H21: 60
G22: No puede exceder los 60 minutos
A23: Competencia a desarrollar | B23: Generar un compilador utilizando como representación intermedia lenguajes ensambladores como RISC-V o Aarch64
A24: Competencia a desarrollar
A26: 2.1 Contenido
A27: No. | B27: Unidad | D27: Tema | F27: Sub Tema
A28: 1 | B28: =IFERROR(__xludf.DUMMYFUNCTION("FILTER('Diseño'!D:D,'Diseño'!H:H=$C$5)"),3.0) -> 3 | D28: =IFERROR(__xludf.DUMMYFUNCTION("FILTER('Diseño'!E:E,'Diseño'!H:H=$C$5)"),"Optimización de la generación de código") -> Optimización de la generación de código | F28: =IFERROR(__xludf.DUMMYFUNCTION("FILTER('Diseño'!F:F,'Diseño'!H:H=$C$5)"),"Algoritmos para dividir en bloques las estructuras de C3D") -> Algoritmos para dividir en bloques las estructuras de C3D
A29: 2 | B29: =IFERROR(__xludf.DUMMYFUNCTION("""COMPUTED_VALUE"""),3.0) -> 3 | D29: =IFERROR(__xludf.DUMMYFUNCTION("""COMPUTED_VALUE"""),"Optimización de la generación de código") -> Optimización de la generación de código | F29: =IFERROR(__xludf.DUMMYFUNCTION("""COMPUTED_VALUE"""),"Algoritmos para optimizar los bloques de código C3d") -> Algoritmos para optimizar los bloques de código C3d
A30: 3 | B30: =IFERROR(__xludf.DUMMYFUNCTION("""COMPUTED_VALUE"""),3.0) -> 3 | D30: =IFERROR(__xludf.DUMMYFUNCTION("""COMPUTED_VALUE"""),"Optimización de la generación de código") -> Optimización de la generación de código | F30: =IFERROR(__xludf.DUMMYFUNCTION("""COMPUTED_VALUE"""),"Algotimo para obtener registros vacíos del descriptor de registros en la generación de código") -> Algotimo para obtener registros vacíos del descriptor de registros en la generación de código
A31: 4
A32: 5
A33: 6
A34: 7
A36: 2.2 Recursos Educativos
A38: Tipo de Recurso a utilizar | B38: Tipo | C38: Valor maximo recomendado en Minutos | D38: Tiempo Aproximado ( unicamente el valor de minutos ) | I38: Validacion
A39: Presentacion | B39: Obligatorio | C39: 30 | I39: =IF(D39<=C39,"Correcto", "Corregir") -> Correcto
A40: Video | B40: Obligatorio | C40: 6 | I40: =IF(D40<=C40,"Correcto", "Corregir") -> Correcto
A41: Lectura | B41: Optativo | C41: 10 | I41: =IF(D41<=C41,"Correcto", "Corregir") -> Correcto
A42: Ejercicio Demostrativo | B42: Obligatorio | C42: 30 | I42: =IF(D42<=C42,"Correcto", "Corregir") -> Correcto
A44: 3. Área de Habilidades (Saber Hacer) | G44: Tiempo Aproximado | H44: 35
G45: Tiene que estar en un rango de 30 a 50 minutos
A46: Actividad 1 (Obligatoria)
A47: Competencia que predomina en la actividad | B47: Generar un compilador utilizando como representación intermedia lenguajes ensambladores como RISC-V o Aarch64
A48: Tipo de Actividad | B48: Ejercicio practico
A49: Ponderación | B49: 0
A50: Tiempo Aproximado
A51: Coloca el tiempo que usar en la actividad, un tiempo sugerido 30 minutos
...

Sheet Proyectos
B2: Proyectos
B4: Curso | C4: ='Diseño'!C4 -> 781 - Organización de Lenguajes y Compiladores 2
B5: Tiempo | C5: =H9+H26+H43 -> 75
B6: Ponderación | C6: =F9+F26+F43 -> 90
B7: La sumatoria de los puntos de los proyectos debe superar el 60% del total de la nota, no puede ser un 100%
A9: 1. Primer Proyecto | E9: Ponderación | F9: 40 | G9: Horas para realizarlo | H9: 35
A10: Obligatorio
